FROM tiangolo/uwsgi-nginx-flask:python3.6-alpine3.7

# not working, 
Traceback (most recent call last):     
  File "/usr/local/lib/python3.6/site-packages/flask/app.py", line 1982, in wsgi_app                                                                          
    response = self.full_dispatch_request()                                    
  File "/usr/local/lib/python3.6/site-packages/flask/app.py", line 1614, in full_dispatch_request                                                             
    rv = self.handle_user_exception(e) 
  File "/usr/local/lib/python3.6/site-packages/flask/app.py", line 1517, in handle_user_exception                                                             
    reraise(exc_type, exc_value, tb)   
  File "/usr/local/lib/python3.6/site-packages/flask/_compat.py", line 33, in reraise                                                                         
    raise value                        
  File "/usr/local/lib/python3.6/site-packages/flask/app.py", line 1612, in full_dispatch_request                                                             
    rv = self.dispatch_request()       
  File "/usr/local/lib/python3.6/site-packages/flask/app.py", line 1598, in dispatch_request                                                                  
    return self.view_functions[rule.endpoint](**req.view_args)                 
  File "./main.py", line 227, in _wrapper                                      
    jwt_auth.get_id_token_payload(jwt_raw)                                     
  File "./main.py", line 213, in get_id_token_payload                          
    public_key = self.get_public_key(key_id)                                   
  File "./main.py", line 207, in get_public_key                                
    self._refresh_certs()              
  File "./main.py", line 191, in _refresh_certs                                
    self._update_certs()               
  File "./main.py", line 201, in _update_certs                                 
    cert_obj = load_pem_x509_certificate(cert_str.encode('utf-8'), default_backend())                                                                         
  File "/usr/local/lib/python3.6/site-packages/cryptography/x509/base.py", line 43, in load_pem_x509_certificate                                              
    return backend.load_pem_x509_certificate(data)                             
  File "/usr/local/lib/python3.6/site-packages/cryptography/hazmat/backends/openssl/backend.py", line 1139, in load_pem_x509_certificate                      
    raise ValueError("Unable to load certificate")                             


RUN apk update \
  && apk add --virtual build-deps gcc python3-dev musl-dev \
  && apk add --no-cache postgresql-dev libffi-dev openssl ca-certificates py-cryptography \
  && update-ca-certificates \
  && pip install psycopg2==2.7.4 cryptography==2.1.4 \
  && apk del build-deps \
  && rm -rf /var/cache/apk/*

COPY ./app /app
RUN pip install -r /app/requirements.txt